ERROR 2025-04-13 12:40:23,992 log Internal Server Error: /
Traceback (most recent call last):
  File "D:\autostudy\.venv\Lib\site-packages\django\core\handlers\exception.py", line 55, in inner
    response = get_response(request)
  File "D:\autostudy\.venv\Lib\site-packages\django\core\handlers\base.py", line 220, in _get_response
    response = response.render()
  File "D:\autostudy\.venv\Lib\site-packages\django\template\response.py", line 114, in render
    self.content = self.rendered_content
                   ^^^^^^^^^^^^^^^^^^^^^
  File "D:\autostudy\.venv\Lib\site-packages\django\template\response.py", line 90, in rendered_content
    template = self.resolve_template(self.template_name)
  File "D:\autostudy\.venv\Lib\site-packages\django\template\response.py", line 72, in resolve_template
    return select_template(template, using=self.using)
  File "D:\autostudy\.venv\Lib\site-packages\django\template\loader.py", line 47, in select_template
    raise TemplateDoesNotExist(", ".join(template_name_list), chain=chain)
django.template.exceptions.TemplateDoesNotExist: index.html
ERROR 2025-04-13 12:40:24,003 basehttp "GET / HTTP/1.1" 500 90178
ERROR 2025-04-15 22:33:00,562 log Internal Server Error: /api/auth/login/
Traceback (most recent call last):
  File "D:\autostudy\.venv\Lib\site-packages\django\db\backends\utils.py", line 105, in _execute
    return self.cursor.execute(sql, params)
           ~~~~~~~~~~~~~~~~~~~^^^^^^^^^^^^^
  File "D:\autostudy\.venv\Lib\site-packages\django\db\backends\sqlite3\base.py", line 354, in execute
    return super().execute(query, params)
           ~~~~~~~~~~~~~~~^^^^^^^^^^^^^^^
sqlite3.OperationalError: no such column: users_user.onboarding_completo

The above exception was the direct cause of the following exception:

Traceback (most recent call last):
  File "D:\autostudy\.venv\Lib\site-packages\django\core\handlers\exception.py", line 55, in inner
    response = get_response(request)
  File "D:\autostudy\.venv\Lib\site-packages\django\core\handlers\base.py", line 197, in _get_response
    response = wrapped_callback(request, *callback_args, **callback_kwargs)
  File "D:\autostudy\.venv\Lib\site-packages\django\views\decorators\csrf.py", line 65, in _view_wrapper
    return view_func(request, *args, **kwargs)
  File "D:\autostudy\.venv\Lib\site-packages\django\views\generic\base.py", line 104, in view
    return self.dispatch(request, *args, **kwargs)
           ~~~~~~~~~~~~~^^^^^^^^^^^^^^^^^^^^^^^^^^
  File "D:\autostudy\.venv\Lib\site-packages\rest_framework\views.py", line 515, in dispatch
    response = self.handle_exception(exc)
  File "D:\autostudy\.venv\Lib\site-packages\rest_framework\views.py", line 475, in handle_exception
    self.raise_uncaught_exception(exc)
    ~~~~~~~~~~~~~~~~~~~~~~~~~~~~~^^^^^
  File "D:\autostudy\.venv\Lib\site-packages\rest_framework\views.py", line 486, in raise_uncaught_exception
    raise exc
  File "D:\autostudy\.venv\Lib\site-packages\rest_framework\views.py", line 512, in dispatch
    response = handler(request, *args, **kwargs)
  File "D:\autostudy\.venv\Lib\site-packages\rest_framework_simplejwt\views.py", line 44, in post
    serializer.is_valid(raise_exception=True)
    ~~~~~~~~~~~~~~~~~~~^^^^^^^^^^^^^^^^^^^^^^
  File "D:\autostudy\.venv\Lib\site-packages\rest_framework\serializers.py", line 225, in is_valid
    self._validated_data = self.run_validation(self.initial_data)
                           ~~~~~~~~~~~~~~~~~~~^^^^^^^^^^^^^^^^^^^
  File "D:\autostudy\.venv\Lib\site-packages\rest_framework\serializers.py", line 447, in run_validation
    value = self.validate(value)
  File "D:\autostudy\backend\autostudy\views.py", line 32, in validate
    data = super().validate(attrs)
  File "D:\autostudy\.venv\Lib\site-packages\rest_framework_simplejwt\serializers.py", line 73, in validate
    data = super().validate(attrs)
  File "D:\autostudy\.venv\Lib\site-packages\rest_framework_simplejwt\serializers.py", line 54, in validate
    self.user = authenticate(**authenticate_kwargs)
                ~~~~~~~~~~~~^^^^^^^^^^^^^^^^^^^^^^^
  File "D:\autostudy\.venv\Lib\site-packages\django\views\decorators\debug.py", line 75, in sensitive_variables_wrapper
    return func(*func_args, **func_kwargs)
  File "D:\autostudy\.venv\Lib\site-packages\django\contrib\auth\__init__.py", line 79, in authenticate
    user = backend.authenticate(request, **credentials)
  File "D:\autostudy\.venv\Lib\site-packages\django\contrib\auth\backends.py", line 42, in authenticate
    user = UserModel._default_manager.get_by_natural_key(username)
  File "D:\autostudy\.venv\Lib\site-packages\django\contrib\auth\base_user.py", line 37, in get_by_natural_key
    return self.get(**{self.model.USERNAME_FIELD: username})
           ~~~~~~~~^^^^^^^^^^^^^^^^^^^^^^^^^^^^^^^^^^^^^^^^^
  File "D:\autostudy\.venv\Lib\site-packages\django\db\models\manager.py", line 87, in manager_method
    return getattr(self.get_queryset(), name)(*args, **kwargs)
           ~~~~~~~~~~~~~~~~~~~~~~~~~~~~~~~~~~^^^^^^^^^^^^^^^^^
  File "D:\autostudy\.venv\Lib\site-packages\django\db\models\query.py", line 645, in get
    num = len(clone)
  File "D:\autostudy\.venv\Lib\site-packages\django\db\models\query.py", line 382, in __len__
    self._fetch_all()
    ~~~~~~~~~~~~~~~^^
  File "D:\autostudy\.venv\Lib\site-packages\django\db\models\query.py", line 1928, in _fetch_all
    self._result_cache = list(self._iterable_class(self))
                         ~~~~^^^^^^^^^^^^^^^^^^^^^^^^^^^^
  File "D:\autostudy\.venv\Lib\site-packages\django\db\models\query.py", line 91, in __iter__
    results = compiler.execute_sql(
        chunked_fetch=self.chunked_fetch, chunk_size=self.chunk_size
    )
  File "D:\autostudy\.venv\Lib\site-packages\django\db\models\sql\compiler.py", line 1574, in execute_sql
    cursor.execute(sql, params)
    ~~~~~~~~~~~~~~^^^^^^^^^^^^^
  File "D:\autostudy\.venv\Lib\site-packages\django\db\backends\utils.py", line 122, in execute
    return super().execute(sql, params)
           ~~~~~~~~~~~~~~~^^^^^^^^^^^^^
  File "D:\autostudy\.venv\Lib\site-packages\django\db\backends\utils.py", line 79, in execute
    return self._execute_with_wrappers(
           ~~~~~~~~~~~~~~~~~~~~~~~~~~~^
        sql, params, many=False, executor=self._execute
        ^^^^^^^^^^^^^^^^^^^^^^^^^^^^^^^^^^^^^^^^^^^^^^^
    )
    ^
  File "D:\autostudy\.venv\Lib\site-packages\django\db\backends\utils.py", line 92, in _execute_with_wrappers
    return executor(sql, params, many, context)
  File "D:\autostudy\.venv\Lib\site-packages\django\db\backends\utils.py", line 100, in _execute
    with self.db.wrap_database_errors:
         ^^^^^^^^^^^^^^^^^^^^^^^^^^^^
  File "D:\autostudy\.venv\Lib\site-packages\django\db\utils.py", line 91, in __exit__
    raise dj_exc_value.with_traceback(traceback) from exc_value
  File "D:\autostudy\.venv\Lib\site-packages\django\db\backends\utils.py", line 105, in _execute
    return self.cursor.execute(sql, params)
           ~~~~~~~~~~~~~~~~~~~^^^^^^^^^^^^^
  File "D:\autostudy\.venv\Lib\site-packages\django\db\backends\sqlite3\base.py", line 354, in execute
    return super().execute(query, params)
           ~~~~~~~~~~~~~~~^^^^^^^^^^^^^^^
django.db.utils.OperationalError: no such column: users_user.onboarding_completo
ERROR 2025-04-15 22:33:00,664 basehttp "POST /api/auth/login/ HTTP/1.1" 500 220057
ERROR 2025-04-15 22:34:38,322 log Internal Server Error: /api/auth/login/
Traceback (most recent call last):
  File "D:\autostudy\.venv\Lib\site-packages\django\db\backends\utils.py", line 105, in _execute
    return self.cursor.execute(sql, params)
           ~~~~~~~~~~~~~~~~~~~^^^^^^^^^^^^^
  File "D:\autostudy\.venv\Lib\site-packages\django\db\backends\sqlite3\base.py", line 354, in execute
    return super().execute(query, params)
           ~~~~~~~~~~~~~~~^^^^^^^^^^^^^^^
sqlite3.OperationalError: no such column: users_user.onboarding_completo

The above exception was the direct cause of the following exception:

Traceback (most recent call last):
  File "D:\autostudy\.venv\Lib\site-packages\django\core\handlers\exception.py", line 55, in inner
    response = get_response(request)
  File "D:\autostudy\.venv\Lib\site-packages\django\core\handlers\base.py", line 197, in _get_response
    response = wrapped_callback(request, *callback_args, **callback_kwargs)
  File "D:\autostudy\.venv\Lib\site-packages\django\views\decorators\csrf.py", line 65, in _view_wrapper
    return view_func(request, *args, **kwargs)
  File "D:\autostudy\.venv\Lib\site-packages\django\views\generic\base.py", line 104, in view
    return self.dispatch(request, *args, **kwargs)
           ~~~~~~~~~~~~~^^^^^^^^^^^^^^^^^^^^^^^^^^
  File "D:\autostudy\.venv\Lib\site-packages\rest_framework\views.py", line 515, in dispatch
    response = self.handle_exception(exc)
  File "D:\autostudy\.venv\Lib\site-packages\rest_framework\views.py", line 475, in handle_exception
    self.raise_uncaught_exception(exc)
    ~~~~~~~~~~~~~~~~~~~~~~~~~~~~~^^^^^
  File "D:\autostudy\.venv\Lib\site-packages\rest_framework\views.py", line 486, in raise_uncaught_exception
    raise exc
  File "D:\autostudy\.venv\Lib\site-packages\rest_framework\views.py", line 512, in dispatch
    response = handler(request, *args, **kwargs)
  File "D:\autostudy\.venv\Lib\site-packages\rest_framework_simplejwt\views.py", line 44, in post
    serializer.is_valid(raise_exception=True)
    ~~~~~~~~~~~~~~~~~~~^^^^^^^^^^^^^^^^^^^^^^
  File "D:\autostudy\.venv\Lib\site-packages\rest_framework\serializers.py", line 225, in is_valid
    self._validated_data = self.run_validation(self.initial_data)
                           ~~~~~~~~~~~~~~~~~~~^^^^^^^^^^^^^^^^^^^
  File "D:\autostudy\.venv\Lib\site-packages\rest_framework\serializers.py", line 447, in run_validation
    value = self.validate(value)
  File "D:\autostudy\backend\autostudy\views.py", line 32, in validate
    data = super().validate(attrs)
  File "D:\autostudy\.venv\Lib\site-packages\rest_framework_simplejwt\serializers.py", line 73, in validate
    data = super().validate(attrs)
  File "D:\autostudy\.venv\Lib\site-packages\rest_framework_simplejwt\serializers.py", line 54, in validate
    self.user = authenticate(**authenticate_kwargs)
                ~~~~~~~~~~~~^^^^^^^^^^^^^^^^^^^^^^^
  File "D:\autostudy\.venv\Lib\site-packages\django\views\decorators\debug.py", line 75, in sensitive_variables_wrapper
    return func(*func_args, **func_kwargs)
  File "D:\autostudy\.venv\Lib\site-packages\django\contrib\auth\__init__.py", line 79, in authenticate
    user = backend.authenticate(request, **credentials)
  File "D:\autostudy\.venv\Lib\site-packages\django\contrib\auth\backends.py", line 42, in authenticate
    user = UserModel._default_manager.get_by_natural_key(username)
  File "D:\autostudy\.venv\Lib\site-packages\django\contrib\auth\base_user.py", line 37, in get_by_natural_key
    return self.get(**{self.model.USERNAME_FIELD: username})
           ~~~~~~~~^^^^^^^^^^^^^^^^^^^^^^^^^^^^^^^^^^^^^^^^^
  File "D:\autostudy\.venv\Lib\site-packages\django\db\models\manager.py", line 87, in manager_method
    return getattr(self.get_queryset(), name)(*args, **kwargs)
           ~~~~~~~~~~~~~~~~~~~~~~~~~~~~~~~~~~^^^^^^^^^^^^^^^^^
  File "D:\autostudy\.venv\Lib\site-packages\django\db\models\query.py", line 645, in get
    num = len(clone)
  File "D:\autostudy\.venv\Lib\site-packages\django\db\models\query.py", line 382, in __len__
    self._fetch_all()
    ~~~~~~~~~~~~~~~^^
  File "D:\autostudy\.venv\Lib\site-packages\django\db\models\query.py", line 1928, in _fetch_all
    self._result_cache = list(self._iterable_class(self))
                         ~~~~^^^^^^^^^^^^^^^^^^^^^^^^^^^^
  File "D:\autostudy\.venv\Lib\site-packages\django\db\models\query.py", line 91, in __iter__
    results = compiler.execute_sql(
        chunked_fetch=self.chunked_fetch, chunk_size=self.chunk_size
    )
  File "D:\autostudy\.venv\Lib\site-packages\django\db\models\sql\compiler.py", line 1574, in execute_sql
    cursor.execute(sql, params)
    ~~~~~~~~~~~~~~^^^^^^^^^^^^^
  File "D:\autostudy\.venv\Lib\site-packages\django\db\backends\utils.py", line 122, in execute
    return super().execute(sql, params)
           ~~~~~~~~~~~~~~~^^^^^^^^^^^^^
  File "D:\autostudy\.venv\Lib\site-packages\django\db\backends\utils.py", line 79, in execute
    return self._execute_with_wrappers(
           ~~~~~~~~~~~~~~~~~~~~~~~~~~~^
        sql, params, many=False, executor=self._execute
        ^^^^^^^^^^^^^^^^^^^^^^^^^^^^^^^^^^^^^^^^^^^^^^^
    )
    ^
  File "D:\autostudy\.venv\Lib\site-packages\django\db\backends\utils.py", line 92, in _execute_with_wrappers
    return executor(sql, params, many, context)
  File "D:\autostudy\.venv\Lib\site-packages\django\db\backends\utils.py", line 100, in _execute
    with self.db.wrap_database_errors:
         ^^^^^^^^^^^^^^^^^^^^^^^^^^^^
  File "D:\autostudy\.venv\Lib\site-packages\django\db\utils.py", line 91, in __exit__
    raise dj_exc_value.with_traceback(traceback) from exc_value
  File "D:\autostudy\.venv\Lib\site-packages\django\db\backends\utils.py", line 105, in _execute
    return self.cursor.execute(sql, params)
           ~~~~~~~~~~~~~~~~~~~^^^^^^^^^^^^^
  File "D:\autostudy\.venv\Lib\site-packages\django\db\backends\sqlite3\base.py", line 354, in execute
    return super().execute(query, params)
           ~~~~~~~~~~~~~~~^^^^^^^^^^^^^^^
django.db.utils.OperationalError: no such column: users_user.onboarding_completo
ERROR 2025-04-15 22:34:38,402 basehttp "POST /api/auth/login/ HTTP/1.1" 500 220057
ERROR 2025-04-15 22:35:03,473 log Internal Server Error: /api/auth/login/
Traceback (most recent call last):
  File "D:\autostudy\.venv\Lib\site-packages\django\db\backends\utils.py", line 105, in _execute
    return self.cursor.execute(sql, params)
           ~~~~~~~~~~~~~~~~~~~^^^^^^^^^^^^^
  File "D:\autostudy\.venv\Lib\site-packages\django\db\backends\sqlite3\base.py", line 354, in execute
    return super().execute(query, params)
           ~~~~~~~~~~~~~~~^^^^^^^^^^^^^^^
sqlite3.OperationalError: no such column: users_user.onboarding_completo

The above exception was the direct cause of the following exception:

Traceback (most recent call last):
  File "D:\autostudy\.venv\Lib\site-packages\django\core\handlers\exception.py", line 55, in inner
    response = get_response(request)
  File "D:\autostudy\.venv\Lib\site-packages\django\core\handlers\base.py", line 197, in _get_response
    response = wrapped_callback(request, *callback_args, **callback_kwargs)
  File "D:\autostudy\.venv\Lib\site-packages\django\views\decorators\csrf.py", line 65, in _view_wrapper
    return view_func(request, *args, **kwargs)
  File "D:\autostudy\.venv\Lib\site-packages\django\views\generic\base.py", line 104, in view
    return self.dispatch(request, *args, **kwargs)
           ~~~~~~~~~~~~~^^^^^^^^^^^^^^^^^^^^^^^^^^
  File "D:\autostudy\.venv\Lib\site-packages\rest_framework\views.py", line 515, in dispatch
    response = self.handle_exception(exc)
  File "D:\autostudy\.venv\Lib\site-packages\rest_framework\views.py", line 475, in handle_exception
    self.raise_uncaught_exception(exc)
    ~~~~~~~~~~~~~~~~~~~~~~~~~~~~~^^^^^
  File "D:\autostudy\.venv\Lib\site-packages\rest_framework\views.py", line 486, in raise_uncaught_exception
    raise exc
  File "D:\autostudy\.venv\Lib\site-packages\rest_framework\views.py", line 512, in dispatch
    response = handler(request, *args, **kwargs)
  File "D:\autostudy\.venv\Lib\site-packages\rest_framework_simplejwt\views.py", line 44, in post
    serializer.is_valid(raise_exception=True)
    ~~~~~~~~~~~~~~~~~~~^^^^^^^^^^^^^^^^^^^^^^
  File "D:\autostudy\.venv\Lib\site-packages\rest_framework\serializers.py", line 225, in is_valid
    self._validated_data = self.run_validation(self.initial_data)
                           ~~~~~~~~~~~~~~~~~~~^^^^^^^^^^^^^^^^^^^
  File "D:\autostudy\.venv\Lib\site-packages\rest_framework\serializers.py", line 447, in run_validation
    value = self.validate(value)
  File "D:\autostudy\backend\autostudy\views.py", line 32, in validate
    data = super().validate(attrs)
  File "D:\autostudy\.venv\Lib\site-packages\rest_framework_simplejwt\serializers.py", line 73, in validate
    data = super().validate(attrs)
  File "D:\autostudy\.venv\Lib\site-packages\rest_framework_simplejwt\serializers.py", line 54, in validate
    self.user = authenticate(**authenticate_kwargs)
                ~~~~~~~~~~~~^^^^^^^^^^^^^^^^^^^^^^^
  File "D:\autostudy\.venv\Lib\site-packages\django\views\decorators\debug.py", line 75, in sensitive_variables_wrapper
    return func(*func_args, **func_kwargs)
  File "D:\autostudy\.venv\Lib\site-packages\django\contrib\auth\__init__.py", line 79, in authenticate
    user = backend.authenticate(request, **credentials)
  File "D:\autostudy\.venv\Lib\site-packages\django\contrib\auth\backends.py", line 42, in authenticate
    user = UserModel._default_manager.get_by_natural_key(username)
  File "D:\autostudy\.venv\Lib\site-packages\django\contrib\auth\base_user.py", line 37, in get_by_natural_key
    return self.get(**{self.model.USERNAME_FIELD: username})
           ~~~~~~~~^^^^^^^^^^^^^^^^^^^^^^^^^^^^^^^^^^^^^^^^^
  File "D:\autostudy\.venv\Lib\site-packages\django\db\models\manager.py", line 87, in manager_method
    return getattr(self.get_queryset(), name)(*args, **kwargs)
           ~~~~~~~~~~~~~~~~~~~~~~~~~~~~~~~~~~^^^^^^^^^^^^^^^^^
  File "D:\autostudy\.venv\Lib\site-packages\django\db\models\query.py", line 645, in get
    num = len(clone)
  File "D:\autostudy\.venv\Lib\site-packages\django\db\models\query.py", line 382, in __len__
    self._fetch_all()
    ~~~~~~~~~~~~~~~^^
  File "D:\autostudy\.venv\Lib\site-packages\django\db\models\query.py", line 1928, in _fetch_all
    self._result_cache = list(self._iterable_class(self))
                         ~~~~^^^^^^^^^^^^^^^^^^^^^^^^^^^^
  File "D:\autostudy\.venv\Lib\site-packages\django\db\models\query.py", line 91, in __iter__
    results = compiler.execute_sql(
        chunked_fetch=self.chunked_fetch, chunk_size=self.chunk_size
    )
  File "D:\autostudy\.venv\Lib\site-packages\django\db\models\sql\compiler.py", line 1574, in execute_sql
    cursor.execute(sql, params)
    ~~~~~~~~~~~~~~^^^^^^^^^^^^^
  File "D:\autostudy\.venv\Lib\site-packages\django\db\backends\utils.py", line 122, in execute
    return super().execute(sql, params)
           ~~~~~~~~~~~~~~~^^^^^^^^^^^^^
  File "D:\autostudy\.venv\Lib\site-packages\django\db\backends\utils.py", line 79, in execute
    return self._execute_with_wrappers(
           ~~~~~~~~~~~~~~~~~~~~~~~~~~~^
        sql, params, many=False, executor=self._execute
        ^^^^^^^^^^^^^^^^^^^^^^^^^^^^^^^^^^^^^^^^^^^^^^^
    )
    ^
  File "D:\autostudy\.venv\Lib\site-packages\django\db\backends\utils.py", line 92, in _execute_with_wrappers
    return executor(sql, params, many, context)
  File "D:\autostudy\.venv\Lib\site-packages\django\db\backends\utils.py", line 100, in _execute
    with self.db.wrap_database_errors:
         ^^^^^^^^^^^^^^^^^^^^^^^^^^^^
  File "D:\autostudy\.venv\Lib\site-packages\django\db\utils.py", line 91, in __exit__
    raise dj_exc_value.with_traceback(traceback) from exc_value
  File "D:\autostudy\.venv\Lib\site-packages\django\db\backends\utils.py", line 105, in _execute
    return self.cursor.execute(sql, params)
           ~~~~~~~~~~~~~~~~~~~^^^^^^^^^^^^^
  File "D:\autostudy\.venv\Lib\site-packages\django\db\backends\sqlite3\base.py", line 354, in execute
    return super().execute(query, params)
           ~~~~~~~~~~~~~~~^^^^^^^^^^^^^^^
django.db.utils.OperationalError: no such column: users_user.onboarding_completo
ERROR 2025-04-15 22:35:03,540 basehttp "POST /api/auth/login/ HTTP/1.1" 500 220057
ERROR 2025-04-15 22:35:36,802 log Internal Server Error: /
Traceback (most recent call last):
  File "D:\autostudy\.venv\Lib\site-packages\django\core\handlers\exception.py", line 55, in inner
    response = get_response(request)
  File "D:\autostudy\.venv\Lib\site-packages\django\core\handlers\base.py", line 220, in _get_response
    response = response.render()
  File "D:\autostudy\.venv\Lib\site-packages\django\template\response.py", line 114, in render
    self.content = self.rendered_content
                   ^^^^^^^^^^^^^^^^^^^^^
  File "D:\autostudy\.venv\Lib\site-packages\django\template\response.py", line 90, in rendered_content
    template = self.resolve_template(self.template_name)
  File "D:\autostudy\.venv\Lib\site-packages\django\template\response.py", line 72, in resolve_template
    return select_template(template, using=self.using)
  File "D:\autostudy\.venv\Lib\site-packages\django\template\loader.py", line 47, in select_template
    raise TemplateDoesNotExist(", ".join(template_name_list), chain=chain)
django.template.exceptions.TemplateDoesNotExist: index.html
ERROR 2025-04-15 22:35:36,816 basehttp "GET / HTTP/1.1" 500 90179
ERROR 2025-04-15 23:11:37,367 log Internal Server Error: /
Traceback (most recent call last):
  File "D:\autostudy\.venv\Lib\site-packages\django\core\handlers\exception.py", line 55, in inner
    response = get_response(request)
  File "D:\autostudy\.venv\Lib\site-packages\django\core\handlers\base.py", line 220, in _get_response
    response = response.render()
  File "D:\autostudy\.venv\Lib\site-packages\django\template\response.py", line 114, in render
    self.content = self.rendered_content
                   ^^^^^^^^^^^^^^^^^^^^^
  File "D:\autostudy\.venv\Lib\site-packages\django\template\response.py", line 90, in rendered_content
    template = self.resolve_template(self.template_name)
  File "D:\autostudy\.venv\Lib\site-packages\django\template\response.py", line 72, in resolve_template
    return select_template(template, using=self.using)
  File "D:\autostudy\.venv\Lib\site-packages\django\template\loader.py", line 47, in select_template
    raise TemplateDoesNotExist(", ".join(template_name_list), chain=chain)
django.template.exceptions.TemplateDoesNotExist: index.html
ERROR 2025-04-15 23:11:37,385 basehttp "GET / HTTP/1.1" 500 90179
ERROR 2025-04-16 07:30:54,799 log Internal Server Error: /api/auth/login/
Traceback (most recent call last):
  File "D:\autostudy\.venv\Lib\site-packages\django\core\handlers\exception.py", line 55, in inner
    response = get_response(request)
  File "D:\autostudy\.venv\Lib\site-packages\django\core\handlers\base.py", line 197, in _get_response
    response = wrapped_callback(request, *callback_args, **callback_kwargs)
  File "D:\autostudy\.venv\Lib\site-packages\django\views\decorators\csrf.py", line 65, in _view_wrapper
    return view_func(request, *args, **kwargs)
  File "D:\autostudy\.venv\Lib\site-packages\django\views\generic\base.py", line 104, in view
    return self.dispatch(request, *args, **kwargs)
           ~~~~~~~~~~~~~^^^^^^^^^^^^^^^^^^^^^^^^^^
  File "D:\autostudy\.venv\Lib\site-packages\rest_framework\views.py", line 515, in dispatch
    response = self.handle_exception(exc)
  File "D:\autostudy\.venv\Lib\site-packages\rest_framework\views.py", line 475, in handle_exception
    self.raise_uncaught_exception(exc)
    ~~~~~~~~~~~~~~~~~~~~~~~~~~~~~^^^^^
  File "D:\autostudy\.venv\Lib\site-packages\rest_framework\views.py", line 486, in raise_uncaught_exception
    raise exc
  File "D:\autostudy\.venv\Lib\site-packages\rest_framework\views.py", line 512, in dispatch
    response = handler(request, *args, **kwargs)
  File "D:\autostudy\.venv\Lib\site-packages\rest_framework_simplejwt\views.py", line 44, in post
    serializer.is_valid(raise_exception=True)
    ~~~~~~~~~~~~~~~~~~~^^^^^^^^^^^^^^^^^^^^^^
  File "D:\autostudy\.venv\Lib\site-packages\rest_framework\serializers.py", line 225, in is_valid
    self._validated_data = self.run_validation(self.initial_data)
                           ~~~~~~~~~~~~~~~~~~~^^^^^^^^^^^^^^^^^^^
  File "D:\autostudy\.venv\Lib\site-packages\rest_framework\serializers.py", line 447, in run_validation
    value = self.validate(value)
  File "D:\autostudy\backend\users\serializers.py", line 37, in validate
    'nome': user.nome,
            ^^^^^^^^^
AttributeError: 'User' object has no attribute 'nome'
ERROR 2025-04-16 07:30:54,861 basehttp "POST /api/auth/login/ HTTP/1.1" 500 116377
ERROR 2025-04-16 20:43:54,832 log Internal Server Error: /api/auth/login/
Traceback (most recent call last):
  File "D:\autostudy\.venv\Lib\site-packages\django\core\handlers\exception.py", line 55, in inner
    response = get_response(request)
  File "D:\autostudy\.venv\Lib\site-packages\django\core\handlers\base.py", line 197, in _get_response
    response = wrapped_callback(request, *callback_args, **callback_kwargs)
  File "D:\autostudy\.venv\Lib\site-packages\django\views\decorators\csrf.py", line 65, in _view_wrapper
    return view_func(request, *args, **kwargs)
  File "D:\autostudy\.venv\Lib\site-packages\django\views\generic\base.py", line 104, in view
    return self.dispatch(request, *args, **kwargs)
           ~~~~~~~~~~~~~^^^^^^^^^^^^^^^^^^^^^^^^^^
  File "D:\autostudy\.venv\Lib\site-packages\rest_framework\views.py", line 515, in dispatch
    response = self.handle_exception(exc)
  File "D:\autostudy\.venv\Lib\site-packages\rest_framework\views.py", line 475, in handle_exception
    self.raise_uncaught_exception(exc)
    ~~~~~~~~~~~~~~~~~~~~~~~~~~~~~^^^^^
  File "D:\autostudy\.venv\Lib\site-packages\rest_framework\views.py", line 486, in raise_uncaught_exception
    raise exc
  File "D:\autostudy\.venv\Lib\site-packages\rest_framework\views.py", line 512, in dispatch
    response = handler(request, *args, **kwargs)
  File "D:\autostudy\.venv\Lib\site-packages\rest_framework_simplejwt\views.py", line 44, in post
    serializer.is_valid(raise_exception=True)
    ~~~~~~~~~~~~~~~~~~~^^^^^^^^^^^^^^^^^^^^^^
  File "D:\autostudy\.venv\Lib\site-packages\rest_framework\serializers.py", line 225, in is_valid
    self._validated_data = self.run_validation(self.initial_data)
                           ~~~~~~~~~~~~~~~~~~~^^^^^^^^^^^^^^^^^^^
  File "D:\autostudy\.venv\Lib\site-packages\rest_framework\serializers.py", line 447, in run_validation
    value = self.validate(value)
  File "D:\autostudy\backend\users\serializers.py", line 37, in validate
    'nome': user.nome,
            ^^^^^^^^^
AttributeError: 'User' object has no attribute 'nome'
ERROR 2025-04-16 20:43:54,847 basehttp "POST /api/auth/login/ HTTP/1.1" 500 116377
ERROR 2025-04-16 21:00:53,456 log Internal Server Error: /api/auth/login/
Traceback (most recent call last):
  File "D:\autostudy\.venv\Lib\site-packages\django\core\handlers\exception.py", line 55, in inner
    response = get_response(request)
  File "D:\autostudy\.venv\Lib\site-packages\django\core\handlers\base.py", line 197, in _get_response
    response = wrapped_callback(request, *callback_args, **callback_kwargs)
  File "D:\autostudy\.venv\Lib\site-packages\django\views\decorators\csrf.py", line 65, in _view_wrapper
    return view_func(request, *args, **kwargs)
  File "D:\autostudy\.venv\Lib\site-packages\django\views\generic\base.py", line 104, in view
    return self.dispatch(request, *args, **kwargs)
           ~~~~~~~~~~~~~^^^^^^^^^^^^^^^^^^^^^^^^^^
  File "D:\autostudy\.venv\Lib\site-packages\rest_framework\views.py", line 515, in dispatch
    response = self.handle_exception(exc)
  File "D:\autostudy\.venv\Lib\site-packages\rest_framework\views.py", line 475, in handle_exception
    self.raise_uncaught_exception(exc)
    ~~~~~~~~~~~~~~~~~~~~~~~~~~~~~^^^^^
  File "D:\autostudy\.venv\Lib\site-packages\rest_framework\views.py", line 486, in raise_uncaught_exception
    raise exc
  File "D:\autostudy\.venv\Lib\site-packages\rest_framework\views.py", line 512, in dispatch
    response = handler(request, *args, **kwargs)
  File "D:\autostudy\.venv\Lib\site-packages\rest_framework_simplejwt\views.py", line 44, in post
    serializer.is_valid(raise_exception=True)
    ~~~~~~~~~~~~~~~~~~~^^^^^^^^^^^^^^^^^^^^^^
  File "D:\autostudy\.venv\Lib\site-packages\rest_framework\serializers.py", line 225, in is_valid
    self._validated_data = self.run_validation(self.initial_data)
                           ~~~~~~~~~~~~~~~~~~~^^^^^^^^^^^^^^^^^^^
  File "D:\autostudy\.venv\Lib\site-packages\rest_framework\serializers.py", line 447, in run_validation
    value = self.validate(value)
  File "D:\autostudy\backend\users\serializers.py", line 37, in validate
    'nome': user.nome,
            ^^^^^^^^^
AttributeError: 'User' object has no attribute 'nome'
ERROR 2025-04-16 21:00:53,598 basehttp "POST /api/auth/login/ HTTP/1.1" 500 116377
ERROR 2025-04-16 21:02:23,469 log Internal Server Error: /api/auth/login/
Traceback (most recent call last):
  File "D:\autostudy\.venv\Lib\site-packages\django\core\handlers\exception.py", line 55, in inner
    response = get_response(request)
  File "D:\autostudy\.venv\Lib\site-packages\django\core\handlers\base.py", line 197, in _get_response
    response = wrapped_callback(request, *callback_args, **callback_kwargs)
  File "D:\autostudy\.venv\Lib\site-packages\django\views\decorators\csrf.py", line 65, in _view_wrapper
    return view_func(request, *args, **kwargs)
  File "D:\autostudy\.venv\Lib\site-packages\django\views\generic\base.py", line 104, in view
    return self.dispatch(request, *args, **kwargs)
           ~~~~~~~~~~~~~^^^^^^^^^^^^^^^^^^^^^^^^^^
  File "D:\autostudy\.venv\Lib\site-packages\rest_framework\views.py", line 515, in dispatch
    response = self.handle_exception(exc)
  File "D:\autostudy\.venv\Lib\site-packages\rest_framework\views.py", line 475, in handle_exception
    self.raise_uncaught_exception(exc)
    ~~~~~~~~~~~~~~~~~~~~~~~~~~~~~^^^^^
  File "D:\autostudy\.venv\Lib\site-packages\rest_framework\views.py", line 486, in raise_uncaught_exception
    raise exc
  File "D:\autostudy\.venv\Lib\site-packages\rest_framework\views.py", line 512, in dispatch
    response = handler(request, *args, **kwargs)
  File "D:\autostudy\.venv\Lib\site-packages\rest_framework_simplejwt\views.py", line 44, in post
    serializer.is_valid(raise_exception=True)
    ~~~~~~~~~~~~~~~~~~~^^^^^^^^^^^^^^^^^^^^^^
  File "D:\autostudy\.venv\Lib\site-packages\rest_framework\serializers.py", line 225, in is_valid
    self._validated_data = self.run_validation(self.initial_data)
                           ~~~~~~~~~~~~~~~~~~~^^^^^^^^^^^^^^^^^^^
  File "D:\autostudy\.venv\Lib\site-packages\rest_framework\serializers.py", line 447, in run_validation
    value = self.validate(value)
  File "D:\autostudy\backend\users\serializers.py", line 37, in validate
    'nome': user.nome,
            ^^^^^^^^^
AttributeError: 'User' object has no attribute 'nome'
ERROR 2025-04-16 21:02:23,481 basehttp "POST /api/auth/login/ HTTP/1.1" 500 116377
ERROR 2025-04-16 21:05:23,344 log Internal Server Error: /api/auth/login/
Traceback (most recent call last):
  File "D:\autostudy\.venv\Lib\site-packages\django\core\handlers\exception.py", line 55, in inner
    response = get_response(request)
  File "D:\autostudy\.venv\Lib\site-packages\django\core\handlers\base.py", line 197, in _get_response
    response = wrapped_callback(request, *callback_args, **callback_kwargs)
  File "D:\autostudy\.venv\Lib\site-packages\django\views\decorators\csrf.py", line 65, in _view_wrapper
    return view_func(request, *args, **kwargs)
  File "D:\autostudy\.venv\Lib\site-packages\django\views\generic\base.py", line 104, in view
    return self.dispatch(request, *args, **kwargs)
           ~~~~~~~~~~~~~^^^^^^^^^^^^^^^^^^^^^^^^^^
  File "D:\autostudy\.venv\Lib\site-packages\rest_framework\views.py", line 515, in dispatch
    response = self.handle_exception(exc)
  File "D:\autostudy\.venv\Lib\site-packages\rest_framework\views.py", line 475, in handle_exception
    self.raise_uncaught_exception(exc)
    ~~~~~~~~~~~~~~~~~~~~~~~~~~~~~^^^^^
  File "D:\autostudy\.venv\Lib\site-packages\rest_framework\views.py", line 486, in raise_uncaught_exception
    raise exc
  File "D:\autostudy\.venv\Lib\site-packages\rest_framework\views.py", line 512, in dispatch
    response = handler(request, *args, **kwargs)
  File "D:\autostudy\.venv\Lib\site-packages\rest_framework_simplejwt\views.py", line 44, in post
    serializer.is_valid(raise_exception=True)
    ~~~~~~~~~~~~~~~~~~~^^^^^^^^^^^^^^^^^^^^^^
  File "D:\autostudy\.venv\Lib\site-packages\rest_framework\serializers.py", line 225, in is_valid
    self._validated_data = self.run_validation(self.initial_data)
                           ~~~~~~~~~~~~~~~~~~~^^^^^^^^^^^^^^^^^^^
  File "D:\autostudy\.venv\Lib\site-packages\rest_framework\serializers.py", line 447, in run_validation
    value = self.validate(value)
  File "D:\autostudy\backend\users\serializers.py", line 37, in validate
    'nome': user.nome,
            ^^^^^^^^^
AttributeError: 'User' object has no attribute 'nome'
ERROR 2025-04-16 21:05:23,368 basehttp "POST /api/auth/login/ HTTP/1.1" 500 116377
ERROR 2025-04-16 21:05:30,159 log Internal Server Error: /api/auth/login/
Traceback (most recent call last):
  File "D:\autostudy\.venv\Lib\site-packages\django\core\handlers\exception.py", line 55, in inner
    response = get_response(request)
  File "D:\autostudy\.venv\Lib\site-packages\django\core\handlers\base.py", line 197, in _get_response
    response = wrapped_callback(request, *callback_args, **callback_kwargs)
  File "D:\autostudy\.venv\Lib\site-packages\django\views\decorators\csrf.py", line 65, in _view_wrapper
    return view_func(request, *args, **kwargs)
  File "D:\autostudy\.venv\Lib\site-packages\django\views\generic\base.py", line 104, in view
    return self.dispatch(request, *args, **kwargs)
           ~~~~~~~~~~~~~^^^^^^^^^^^^^^^^^^^^^^^^^^
  File "D:\autostudy\.venv\Lib\site-packages\rest_framework\views.py", line 515, in dispatch
    response = self.handle_exception(exc)
  File "D:\autostudy\.venv\Lib\site-packages\rest_framework\views.py", line 475, in handle_exception
    self.raise_uncaught_exception(exc)
    ~~~~~~~~~~~~~~~~~~~~~~~~~~~~~^^^^^
  File "D:\autostudy\.venv\Lib\site-packages\rest_framework\views.py", line 486, in raise_uncaught_exception
    raise exc
  File "D:\autostudy\.venv\Lib\site-packages\rest_framework\views.py", line 512, in dispatch
    response = handler(request, *args, **kwargs)
  File "D:\autostudy\.venv\Lib\site-packages\rest_framework_simplejwt\views.py", line 44, in post
    serializer.is_valid(raise_exception=True)
    ~~~~~~~~~~~~~~~~~~~^^^^^^^^^^^^^^^^^^^^^^
  File "D:\autostudy\.venv\Lib\site-packages\rest_framework\serializers.py", line 225, in is_valid
    self._validated_data = self.run_validation(self.initial_data)
                           ~~~~~~~~~~~~~~~~~~~^^^^^^^^^^^^^^^^^^^
  File "D:\autostudy\.venv\Lib\site-packages\rest_framework\serializers.py", line 447, in run_validation
    value = self.validate(value)
  File "D:\autostudy\backend\users\serializers.py", line 37, in validate
    'nome': user.nome,
            ^^^^^^^^^
AttributeError: 'User' object has no attribute 'nome'
ERROR 2025-04-16 21:05:30,192 basehttp "POST /api/auth/login/ HTTP/1.1" 500 116377
ERROR 2025-04-16 21:07:59,319 log Internal Server Error: /api/auth/login/
Traceback (most recent call last):
  File "D:\autostudy\.venv\Lib\site-packages\django\core\handlers\exception.py", line 55, in inner
    response = get_response(request)
  File "D:\autostudy\.venv\Lib\site-packages\django\core\handlers\base.py", line 197, in _get_response
    response = wrapped_callback(request, *callback_args, **callback_kwargs)
  File "D:\autostudy\.venv\Lib\site-packages\django\views\decorators\csrf.py", line 65, in _view_wrapper
    return view_func(request, *args, **kwargs)
  File "D:\autostudy\.venv\Lib\site-packages\django\views\generic\base.py", line 104, in view
    return self.dispatch(request, *args, **kwargs)
           ~~~~~~~~~~~~~^^^^^^^^^^^^^^^^^^^^^^^^^^
  File "D:\autostudy\.venv\Lib\site-packages\rest_framework\views.py", line 515, in dispatch
    response = self.handle_exception(exc)
  File "D:\autostudy\.venv\Lib\site-packages\rest_framework\views.py", line 475, in handle_exception
    self.raise_uncaught_exception(exc)
    ~~~~~~~~~~~~~~~~~~~~~~~~~~~~~^^^^^
  File "D:\autostudy\.venv\Lib\site-packages\rest_framework\views.py", line 486, in raise_uncaught_exception
    raise exc
  File "D:\autostudy\.venv\Lib\site-packages\rest_framework\views.py", line 512, in dispatch
    response = handler(request, *args, **kwargs)
  File "D:\autostudy\.venv\Lib\site-packages\rest_framework_simplejwt\views.py", line 44, in post
    serializer.is_valid(raise_exception=True)
    ~~~~~~~~~~~~~~~~~~~^^^^^^^^^^^^^^^^^^^^^^
  File "D:\autostudy\.venv\Lib\site-packages\rest_framework\serializers.py", line 225, in is_valid
    self._validated_data = self.run_validation(self.initial_data)
                           ~~~~~~~~~~~~~~~~~~~^^^^^^^^^^^^^^^^^^^
  File "D:\autostudy\.venv\Lib\site-packages\rest_framework\serializers.py", line 447, in run_validation
    value = self.validate(value)
  File "D:\autostudy\backend\users\serializers.py", line 37, in validate
    'nome': user.nome,
            ^^^^^^^^^
AttributeError: 'User' object has no attribute 'nome'
ERROR 2025-04-16 21:07:59,335 basehttp "POST /api/auth/login/ HTTP/1.1" 500 116377
ERROR 2025-04-16 21:08:11,962 log Internal Server Error: /api/auth/login/
Traceback (most recent call last):
  File "D:\autostudy\.venv\Lib\site-packages\django\core\handlers\exception.py", line 55, in inner
    response = get_response(request)
  File "D:\autostudy\.venv\Lib\site-packages\django\core\handlers\base.py", line 197, in _get_response
    response = wrapped_callback(request, *callback_args, **callback_kwargs)
  File "D:\autostudy\.venv\Lib\site-packages\django\views\decorators\csrf.py", line 65, in _view_wrapper
    return view_func(request, *args, **kwargs)
  File "D:\autostudy\.venv\Lib\site-packages\django\views\generic\base.py", line 104, in view
    return self.dispatch(request, *args, **kwargs)
           ~~~~~~~~~~~~~^^^^^^^^^^^^^^^^^^^^^^^^^^
  File "D:\autostudy\.venv\Lib\site-packages\rest_framework\views.py", line 515, in dispatch
    response = self.handle_exception(exc)
  File "D:\autostudy\.venv\Lib\site-packages\rest_framework\views.py", line 475, in handle_exception
    self.raise_uncaught_exception(exc)
    ~~~~~~~~~~~~~~~~~~~~~~~~~~~~~^^^^^
  File "D:\autostudy\.venv\Lib\site-packages\rest_framework\views.py", line 486, in raise_uncaught_exception
    raise exc
  File "D:\autostudy\.venv\Lib\site-packages\rest_framework\views.py", line 512, in dispatch
    response = handler(request, *args, **kwargs)
  File "D:\autostudy\.venv\Lib\site-packages\rest_framework_simplejwt\views.py", line 44, in post
    serializer.is_valid(raise_exception=True)
    ~~~~~~~~~~~~~~~~~~~^^^^^^^^^^^^^^^^^^^^^^
  File "D:\autostudy\.venv\Lib\site-packages\rest_framework\serializers.py", line 225, in is_valid
    self._validated_data = self.run_validation(self.initial_data)
                           ~~~~~~~~~~~~~~~~~~~^^^^^^^^^^^^^^^^^^^
  File "D:\autostudy\.venv\Lib\site-packages\rest_framework\serializers.py", line 447, in run_validation
    value = self.validate(value)
  File "D:\autostudy\backend\users\serializers.py", line 37, in validate
    'nome': user.nome,
            ^^^^^^^^^
AttributeError: 'User' object has no attribute 'nome'
ERROR 2025-04-16 21:08:11,978 basehttp "POST /api/auth/login/ HTTP/1.1" 500 116377
ERROR 2025-04-16 21:13:25,263 log Internal Server Error: /api/auth/login/
Traceback (most recent call last):
  File "D:\autostudy\.venv\Lib\site-packages\django\core\handlers\exception.py", line 55, in inner
    response = get_response(request)
  File "D:\autostudy\.venv\Lib\site-packages\django\core\handlers\base.py", line 197, in _get_response
    response = wrapped_callback(request, *callback_args, **callback_kwargs)
  File "D:\autostudy\.venv\Lib\site-packages\django\views\decorators\csrf.py", line 65, in _view_wrapper
    return view_func(request, *args, **kwargs)
  File "D:\autostudy\.venv\Lib\site-packages\django\views\generic\base.py", line 104, in view
    return self.dispatch(request, *args, **kwargs)
           ~~~~~~~~~~~~~^^^^^^^^^^^^^^^^^^^^^^^^^^
  File "D:\autostudy\.venv\Lib\site-packages\rest_framework\views.py", line 515, in dispatch
    response = self.handle_exception(exc)
  File "D:\autostudy\.venv\Lib\site-packages\rest_framework\views.py", line 475, in handle_exception
    self.raise_uncaught_exception(exc)
    ~~~~~~~~~~~~~~~~~~~~~~~~~~~~~^^^^^
  File "D:\autostudy\.venv\Lib\site-packages\rest_framework\views.py", line 486, in raise_uncaught_exception
    raise exc
  File "D:\autostudy\.venv\Lib\site-packages\rest_framework\views.py", line 512, in dispatch
    response = handler(request, *args, **kwargs)
  File "D:\autostudy\.venv\Lib\site-packages\rest_framework_simplejwt\views.py", line 44, in post
    serializer.is_valid(raise_exception=True)
    ~~~~~~~~~~~~~~~~~~~^^^^^^^^^^^^^^^^^^^^^^
  File "D:\autostudy\.venv\Lib\site-packages\rest_framework\serializers.py", line 225, in is_valid
    self._validated_data = self.run_validation(self.initial_data)
                           ~~~~~~~~~~~~~~~~~~~^^^^^^^^^^^^^^^^^^^
  File "D:\autostudy\.venv\Lib\site-packages\rest_framework\serializers.py", line 447, in run_validation
    value = self.validate(value)
  File "D:\autostudy\backend\users\serializers.py", line 37, in validate
    'nome': user.nome,
            ^^^^^^^^^
AttributeError: 'User' object has no attribute 'nome'
ERROR 2025-04-16 21:13:25,293 basehttp "POST /api/auth/login/ HTTP/1.1" 500 118934
ERROR 2025-04-16 21:13:42,437 log Internal Server Error: /api/auth/login/
Traceback (most recent call last):
  File "D:\autostudy\.venv\Lib\site-packages\django\core\handlers\exception.py", line 55, in inner
    response = get_response(request)
  File "D:\autostudy\.venv\Lib\site-packages\django\core\handlers\base.py", line 197, in _get_response
    response = wrapped_callback(request, *callback_args, **callback_kwargs)
  File "D:\autostudy\.venv\Lib\site-packages\django\views\decorators\csrf.py", line 65, in _view_wrapper
    return view_func(request, *args, **kwargs)
  File "D:\autostudy\.venv\Lib\site-packages\django\views\generic\base.py", line 104, in view
    return self.dispatch(request, *args, **kwargs)
           ~~~~~~~~~~~~~^^^^^^^^^^^^^^^^^^^^^^^^^^
  File "D:\autostudy\.venv\Lib\site-packages\rest_framework\views.py", line 515, in dispatch
    response = self.handle_exception(exc)
  File "D:\autostudy\.venv\Lib\site-packages\rest_framework\views.py", line 475, in handle_exception
    self.raise_uncaught_exception(exc)
    ~~~~~~~~~~~~~~~~~~~~~~~~~~~~~^^^^^
  File "D:\autostudy\.venv\Lib\site-packages\rest_framework\views.py", line 486, in raise_uncaught_exception
    raise exc
  File "D:\autostudy\.venv\Lib\site-packages\rest_framework\views.py", line 512, in dispatch
    response = handler(request, *args, **kwargs)
  File "D:\autostudy\.venv\Lib\site-packages\rest_framework_simplejwt\views.py", line 44, in post
    serializer.is_valid(raise_exception=True)
    ~~~~~~~~~~~~~~~~~~~^^^^^^^^^^^^^^^^^^^^^^
  File "D:\autostudy\.venv\Lib\site-packages\rest_framework\serializers.py", line 225, in is_valid
    self._validated_data = self.run_validation(self.initial_data)
                           ~~~~~~~~~~~~~~~~~~~^^^^^^^^^^^^^^^^^^^
  File "D:\autostudy\.venv\Lib\site-packages\rest_framework\serializers.py", line 447, in run_validation
    value = self.validate(value)
  File "D:\autostudy\backend\users\serializers.py", line 37, in validate
    'nome': user.nome,
            ^^^^^^^^^
AttributeError: 'User' object has no attribute 'nome'
ERROR 2025-04-16 21:13:42,450 basehttp "POST /api/auth/login/ HTTP/1.1" 500 118934
ERROR 2025-04-16 21:13:59,250 log Internal Server Error: /api/auth/login/
Traceback (most recent call last):
  File "D:\autostudy\.venv\Lib\site-packages\django\core\handlers\exception.py", line 55, in inner
    response = get_response(request)
  File "D:\autostudy\.venv\Lib\site-packages\django\core\handlers\base.py", line 197, in _get_response
    response = wrapped_callback(request, *callback_args, **callback_kwargs)
  File "D:\autostudy\.venv\Lib\site-packages\django\views\decorators\csrf.py", line 65, in _view_wrapper
    return view_func(request, *args, **kwargs)
  File "D:\autostudy\.venv\Lib\site-packages\django\views\generic\base.py", line 104, in view
    return self.dispatch(request, *args, **kwargs)
           ~~~~~~~~~~~~~^^^^^^^^^^^^^^^^^^^^^^^^^^
  File "D:\autostudy\.venv\Lib\site-packages\rest_framework\views.py", line 515, in dispatch
    response = self.handle_exception(exc)
  File "D:\autostudy\.venv\Lib\site-packages\rest_framework\views.py", line 475, in handle_exception
    self.raise_uncaught_exception(exc)
    ~~~~~~~~~~~~~~~~~~~~~~~~~~~~~^^^^^
  File "D:\autostudy\.venv\Lib\site-packages\rest_framework\views.py", line 486, in raise_uncaught_exception
    raise exc
  File "D:\autostudy\.venv\Lib\site-packages\rest_framework\views.py", line 512, in dispatch
    response = handler(request, *args, **kwargs)
  File "D:\autostudy\.venv\Lib\site-packages\rest_framework_simplejwt\views.py", line 44, in post
    serializer.is_valid(raise_exception=True)
    ~~~~~~~~~~~~~~~~~~~^^^^^^^^^^^^^^^^^^^^^^
  File "D:\autostudy\.venv\Lib\site-packages\rest_framework\serializers.py", line 225, in is_valid
    self._validated_data = self.run_validation(self.initial_data)
                           ~~~~~~~~~~~~~~~~~~~^^^^^^^^^^^^^^^^^^^
  File "D:\autostudy\.venv\Lib\site-packages\rest_framework\serializers.py", line 447, in run_validation
    value = self.validate(value)
  File "D:\autostudy\backend\users\serializers.py", line 37, in validate
    'nome': user.nome,
            ^^^^^^^^^
AttributeError: 'User' object has no attribute 'nome'
ERROR 2025-04-16 21:13:59,262 basehttp "POST /api/auth/login/ HTTP/1.1" 500 116377
ERROR 2025-04-16 21:15:07,317 log Internal Server Error: /api/auth/login/
Traceback (most recent call last):
  File "D:\autostudy\.venv\Lib\site-packages\django\core\handlers\exception.py", line 55, in inner
    response = get_response(request)
  File "D:\autostudy\.venv\Lib\site-packages\django\core\handlers\base.py", line 197, in _get_response
    response = wrapped_callback(request, *callback_args, **callback_kwargs)
  File "D:\autostudy\.venv\Lib\site-packages\django\views\decorators\csrf.py", line 65, in _view_wrapper
    return view_func(request, *args, **kwargs)
  File "D:\autostudy\.venv\Lib\site-packages\django\views\generic\base.py", line 104, in view
    return self.dispatch(request, *args, **kwargs)
           ~~~~~~~~~~~~~^^^^^^^^^^^^^^^^^^^^^^^^^^
  File "D:\autostudy\.venv\Lib\site-packages\rest_framework\views.py", line 515, in dispatch
    response = self.handle_exception(exc)
  File "D:\autostudy\.venv\Lib\site-packages\rest_framework\views.py", line 475, in handle_exception
    self.raise_uncaught_exception(exc)
    ~~~~~~~~~~~~~~~~~~~~~~~~~~~~~^^^^^
  File "D:\autostudy\.venv\Lib\site-packages\rest_framework\views.py", line 486, in raise_uncaught_exception
    raise exc
  File "D:\autostudy\.venv\Lib\site-packages\rest_framework\views.py", line 512, in dispatch
    response = handler(request, *args, **kwargs)
  File "D:\autostudy\.venv\Lib\site-packages\rest_framework_simplejwt\views.py", line 44, in post
    serializer.is_valid(raise_exception=True)
    ~~~~~~~~~~~~~~~~~~~^^^^^^^^^^^^^^^^^^^^^^
  File "D:\autostudy\.venv\Lib\site-packages\rest_framework\serializers.py", line 225, in is_valid
    self._validated_data = self.run_validation(self.initial_data)
                           ~~~~~~~~~~~~~~~~~~~^^^^^^^^^^^^^^^^^^^
  File "D:\autostudy\.venv\Lib\site-packages\rest_framework\serializers.py", line 447, in run_validation
    value = self.validate(value)
  File "D:\autostudy\backend\users\serializers.py", line 37, in validate
    'nome': user.nome,
            ^^^^^^^^^
AttributeError: 'User' object has no attribute 'nome'
ERROR 2025-04-16 21:15:07,333 basehttp "POST /api/auth/login/ HTTP/1.1" 500 116377
ERROR 2025-04-16 21:15:54,545 log Internal Server Error: /api/auth/login/
Traceback (most recent call last):
  File "D:\autostudy\.venv\Lib\site-packages\django\core\handlers\exception.py", line 55, in inner
    response = get_response(request)
  File "D:\autostudy\.venv\Lib\site-packages\django\core\handlers\base.py", line 197, in _get_response
    response = wrapped_callback(request, *callback_args, **callback_kwargs)
  File "D:\autostudy\.venv\Lib\site-packages\django\views\decorators\csrf.py", line 65, in _view_wrapper
    return view_func(request, *args, **kwargs)
  File "D:\autostudy\.venv\Lib\site-packages\django\views\generic\base.py", line 104, in view
    return self.dispatch(request, *args, **kwargs)
           ~~~~~~~~~~~~~^^^^^^^^^^^^^^^^^^^^^^^^^^
  File "D:\autostudy\.venv\Lib\site-packages\rest_framework\views.py", line 515, in dispatch
    response = self.handle_exception(exc)
  File "D:\autostudy\.venv\Lib\site-packages\rest_framework\views.py", line 475, in handle_exception
    self.raise_uncaught_exception(exc)
    ~~~~~~~~~~~~~~~~~~~~~~~~~~~~~^^^^^
  File "D:\autostudy\.venv\Lib\site-packages\rest_framework\views.py", line 486, in raise_uncaught_exception
    raise exc
  File "D:\autostudy\.venv\Lib\site-packages\rest_framework\views.py", line 512, in dispatch
    response = handler(request, *args, **kwargs)
  File "D:\autostudy\.venv\Lib\site-packages\rest_framework_simplejwt\views.py", line 44, in post
    serializer.is_valid(raise_exception=True)
    ~~~~~~~~~~~~~~~~~~~^^^^^^^^^^^^^^^^^^^^^^
  File "D:\autostudy\.venv\Lib\site-packages\rest_framework\serializers.py", line 225, in is_valid
    self._validated_data = self.run_validation(self.initial_data)
                           ~~~~~~~~~~~~~~~~~~~^^^^^^^^^^^^^^^^^^^
  File "D:\autostudy\.venv\Lib\site-packages\rest_framework\serializers.py", line 447, in run_validation
    value = self.validate(value)
  File "D:\autostudy\backend\users\serializers.py", line 37, in validate
    'nome': user.nome,
            ^^^^^^^^^
AttributeError: 'User' object has no attribute 'nome'
ERROR 2025-04-16 21:15:54,638 basehttp "POST /api/auth/login/ HTTP/1.1" 500 116377
ERROR 2025-04-16 23:21:47,965 log Internal Server Error: /api/auth/login/
Traceback (most recent call last):
  File "D:\autostudy\.venv\Lib\site-packages\django\core\handlers\exception.py", line 55, in inner
    response = get_response(request)
  File "D:\autostudy\.venv\Lib\site-packages\django\core\handlers\base.py", line 197, in _get_response
    response = wrapped_callback(request, *callback_args, **callback_kwargs)
  File "D:\autostudy\.venv\Lib\site-packages\django\views\decorators\csrf.py", line 65, in _view_wrapper
    return view_func(request, *args, **kwargs)
  File "D:\autostudy\.venv\Lib\site-packages\django\views\generic\base.py", line 104, in view
    return self.dispatch(request, *args, **kwargs)
           ~~~~~~~~~~~~~^^^^^^^^^^^^^^^^^^^^^^^^^^
  File "D:\autostudy\.venv\Lib\site-packages\rest_framework\views.py", line 515, in dispatch
    response = self.handle_exception(exc)
  File "D:\autostudy\.venv\Lib\site-packages\rest_framework\views.py", line 475, in handle_exception
    self.raise_uncaught_exception(exc)
    ~~~~~~~~~~~~~~~~~~~~~~~~~~~~~^^^^^
  File "D:\autostudy\.venv\Lib\site-packages\rest_framework\views.py", line 486, in raise_uncaught_exception
    raise exc
  File "D:\autostudy\.venv\Lib\site-packages\rest_framework\views.py", line 512, in dispatch
    response = handler(request, *args, **kwargs)
  File "D:\autostudy\.venv\Lib\site-packages\rest_framework_simplejwt\views.py", line 44, in post
    serializer.is_valid(raise_exception=True)
    ~~~~~~~~~~~~~~~~~~~^^^^^^^^^^^^^^^^^^^^^^
  File "D:\autostudy\.venv\Lib\site-packages\rest_framework\serializers.py", line 225, in is_valid
    self._validated_data = self.run_validation(self.initial_data)
                           ~~~~~~~~~~~~~~~~~~~^^^^^^^^^^^^^^^^^^^
  File "D:\autostudy\.venv\Lib\site-packages\rest_framework\serializers.py", line 447, in run_validation
    value = self.validate(value)
  File "D:\autostudy\backend\users\serializers.py", line 45, in validate
    data['avatar'] = user.avatar.url if user.avatar else ''
                                        ^^^^^^^^^^^
AttributeError: 'User' object has no attribute 'avatar'
ERROR 2025-04-16 23:21:47,998 basehttp "POST /api/auth/login/ HTTP/1.1" 500 116716
ERROR 2025-04-16 23:22:51,584 log Internal Server Error: /api/auth/login/
Traceback (most recent call last):
  File "D:\autostudy\.venv\Lib\site-packages\django\core\handlers\exception.py", line 55, in inner
    response = get_response(request)
  File "D:\autostudy\.venv\Lib\site-packages\django\core\handlers\base.py", line 197, in _get_response
    response = wrapped_callback(request, *callback_args, **callback_kwargs)
  File "D:\autostudy\.venv\Lib\site-packages\django\views\decorators\csrf.py", line 65, in _view_wrapper
    return view_func(request, *args, **kwargs)
  File "D:\autostudy\.venv\Lib\site-packages\django\views\generic\base.py", line 104, in view
    return self.dispatch(request, *args, **kwargs)
           ~~~~~~~~~~~~~^^^^^^^^^^^^^^^^^^^^^^^^^^
  File "D:\autostudy\.venv\Lib\site-packages\rest_framework\views.py", line 515, in dispatch
    response = self.handle_exception(exc)
  File "D:\autostudy\.venv\Lib\site-packages\rest_framework\views.py", line 475, in handle_exception
    self.raise_uncaught_exception(exc)
    ~~~~~~~~~~~~~~~~~~~~~~~~~~~~~^^^^^
  File "D:\autostudy\.venv\Lib\site-packages\rest_framework\views.py", line 486, in raise_uncaught_exception
    raise exc
  File "D:\autostudy\.venv\Lib\site-packages\rest_framework\views.py", line 512, in dispatch
    response = handler(request, *args, **kwargs)
  File "D:\autostudy\.venv\Lib\site-packages\rest_framework_simplejwt\views.py", line 44, in post
    serializer.is_valid(raise_exception=True)
    ~~~~~~~~~~~~~~~~~~~^^^^^^^^^^^^^^^^^^^^^^
  File "D:\autostudy\.venv\Lib\site-packages\rest_framework\serializers.py", line 225, in is_valid
    self._validated_data = self.run_validation(self.initial_data)
                           ~~~~~~~~~~~~~~~~~~~^^^^^^^^^^^^^^^^^^^
  File "D:\autostudy\.venv\Lib\site-packages\rest_framework\serializers.py", line 447, in run_validation
    value = self.validate(value)
  File "D:\autostudy\backend\users\serializers.py", line 45, in validate
    data['avatar'] = user.avatar.url if user.avatar else ''
                                        ^^^^^^^^^^^
AttributeError: 'User' object has no attribute 'avatar'
ERROR 2025-04-16 23:22:51,601 basehttp "POST /api/auth/login/ HTTP/1.1" 500 116716
